Workbook
Name Slicer_Kategori_Barang: #N/A
Name Slicer_Lokasi_Penyimpanan: #N/A
Name Slicer_Status: #N/A
Name Slicer_Supplier: #N/A

Sheet Raw Data
A1: A | B1: B | C1: C | D1: D | E1: E | F1: F | G1: G | H1: H | I1: I | J1: J | K1: K | L1: L | M1: M | N1: N | O1: O
A2: APD-154 | B2: Masker Medis 3-Ply | C2: APD | D2: Box | E2: CV Labware Indonesia | F2: 2025-08-25 | G2: 2025-09-07 | H2: 100 | I2: 84 | J2: =H2-I2 -> 16 | K2: 45000 | L2: =J2*K2 -> 720000 | M2: Gudang B (Dingin) | N2: =IF(J2<=0,"Habis",IF(J2<=5,"Menipis","Tersedia")) -> Tersedia | O2: Dr. Ahmad Fauzi
A3: ALA-166 | B3: Gelas Kimia 250mL | C3: Alat Gelas | D3: Pcs | E3: CV Labware Indonesia | F3: 2025-05-08 | G3: 2025-05-15 | H3: 200 | I3: 12 | J3: =H3-I3 -> 188 | K3: 45000 | L3: =J3*K3 -> 8460000 | M3: Gudang Utama A | N3: =IF(J3<=0,"Habis",IF(J3<=5,"Menipis","Tersedia")) -> Tersedia | O3: Dewi Lestari, Ph.D.
A4: ALA-145 | B4: Tabung Reaksi | C4: Alat Gelas | D4: Pcs | E4: PT Anugerah Analitika | F4: 2025-05-15 | H4: 100 | I4: 0 | J4: =H4-I4 -> 100 | K4: 12000 | L4: =J4*K4 -> 1200000 | M4: Rak Alat C | N4: =IF(J4<=0,"Habis",IF(J4<=5,"Menipis","Tersedia")) -> Tersedia | O4: Fajar Nugroho
A5: ALA-117 | B5: Mini Centrifuge | C5: Alat Laboratorium | D5: Unit | E5: CV Labware Indonesia | F5: 2025-11-11 | G5: 2025-11-14 | H5: 2 | I5: 1 | J5: =H5-I5 -> 1 | K5: 4500000 | L5: =J5*K5 -> 4500000 | M5: Lemari Flammable | N5: =IF(J5<=0,"Habis",IF(J5<=5,"Menipis","Tersedia")) -> Menipis | O5: Rina Wijaya
A6: ALA-168 | B6: Pipet Volume 10mL | C6: Alat Gelas | D6: Pcs | E6: PT Medika Utama | F6: 2025-10-09 | G6: 2025-10-20 | H6: 100 | I6: 9 | J6: =H6-I6 -> 91 | K6: 35000 | L6: =J6*K6 -> 3185000 | M6: Rak Alat C | N6: =IF(J6<=0,"Habis",IF(J6<=5,"Menipis","Tersedia")) -> Tersedia | O6: Rina Wijaya
A7: APD-164 | B7: Jas Laboratorium | C7: APD | D7: Box | E7: PT Global Labora Mandiri | F7: 2025-05-03 | H7: 10 | I7: 0 | J7: =H7-I7 -> 10 | K7: 150000 | L7: =J7*K7 -> 1500000 | M7: Lemari Flammable | N7: =IF(J7<=0,"Habis",IF(J7<=5,"Menipis","Tersedia")) -> Tersedia | O7: Rina Wijaya
A8: ALA-184 | B8: pH Meter | C8: Alat Laboratorium | D8: Unit | E8: CV Biotech Pratama | F8: 2025-07-16 | G8: 2025-07-18 | H8: 5 | I8: 2 | J8: =H8-I8 -> 3 | K8: 1850000 | L8: =J8*K8 -> 5550000 | M8: Gudang B (Dingin) | N8: =IF(J8<=0,"Habis",IF(J8<=5,"Menipis","Tersedia")) -> Menipis | O8: Siti Aminah, S.Si.
A9: REA-121 | B9: Buffer TAE 50X | C9: Reagen | D9: Kit | E9: PT Merck Chemical Indonesia | F9: 2025-08-01 | H9: 100 | I9: 0 | J9: =H9-I9 -> 100 | K9: 350000 | L9: =J9*K9 -> 35000000 | M9: Lemari Flammable | N9: =IF(J9<=0,"Habis",IF(J9<=5,"Menipis","Tersedia")) -> Tersedia | O9: Dewi Lestari, Ph.D.
A10: ALA-179 | B10: Vortex Mixer | C10: Alat Laboratorium | D10: Unit | E10: PT Chemlab Mandiri | F10: 2025-05-17 | H10: 5 | I10: 0 | J10: =H10-I10 -> 5 | K10: 3800000 | L10: =J10*K10 -> 19000000 | M10: Gudang Utama A | N10: =IF(J10<=0,"Habis",IF(J10<=5,"Menipis","Tersedia")) -> Menipis | O10: Budi Santoso, M.Si.
A11: BAH-199 | B11: Kertas Saring Whatman | C11: Bahan Habis Pakai | D11: Pack | E11: PT Global Labora Mandiri | F11: 2025-06-17 | H11: 100 | I11: 0 | J11: =H11-I11 -> 100 | K11: 240000 | L11: =J11*K11 -> 24000000 | M11: Rak Alat C | N11: =IF(J11<=0,"Habis",IF(J11<=5,"Menipis","Tersedia")) -> Tersedia | O11: Agus Kurniawan
A12: APD-142 | B12: Masker Medis 3-Ply | C12: APD | D12: Box | E12: PT Medika Utama | F12: 2025-05-15 | G12: 2025-05-22 | H12: 100 | I12: 21 | J12: =H12-I12 -> 79 | K12: 45000 | L12: =J12*K12 -> 3555000 | M12: Gudang Utama A | N12: =IF(J12<=0,"Habis",IF(J12<=5,"Menipis","Tersedia")) -> Tersedia | O12: Rina Wijaya
A13: BAH-194 | B13: Metanol P.A. | C13: Bahan Kimia | D13: Botol | E13: PT Chemlab Mandiri | F13: 2025-09-05 | G13: 2025-09-13 | H13: 150 | I13: 43 | J13: =H13-I13 -> 107 | K13: 280000 | L13: =J13*K13 -> 29960000 | M13: Loker APD Sentral | N13: =IF(J13<=0,"Habis",IF(J13<=5,"Menipis","Tersedia")) -> Tersedia | O13: Hendra Setiawan
A14: BAH-151 | B14: Parafilm M Roll | C14: Bahan Habis Pakai | D14: Pack | E14: PT Global Labora Mandiri | F14: 2025-10-27 | G14: 2025-11-08 | H14: 50 | I14: 32 | J14: =H14-I14 -> 18 | K14: 650000 | L14: =J14*K14 -> 11700000 | M14: Loker APD Sentral | N14: =IF(J14<=0,"Habis",IF(J14<=5,"Menipis","Tersedia")) -> Tersedia | O14: Fajar Nugroho
A15: ALA-156 | B15: Tabung Reaksi | C15: Alat Gelas | D15: Pcs | E15: CV Biotech Pratama | F15: 2025-01-02 | G15: 2025-01-08 | H15: 100 | I15: 7 | J15: =H15-I15 -> 93 | K15: 12000 | L15: =J15*K15 -> 1116000 | M15: Gudang Utama A | N15: =IF(J15<=0,"Habis",IF(J15<=5,"Menipis","Tersedia")) -> Tersedia | O15: Fajar Nugroho
A16: REA-113 | B16: PCR Master Mix 2X | C16: Reagen | D16: Kit | E16: PT Advanced Nano Tech | F16: 2025-03-13 | G16: 2025-03-22 | H16: 100 | I16: 100 | J16: =H16-I16 -> 0 | K16: 850000 | L16: =J16*K16 -> 0 | M16: Lemari Flammable | N16: =IF(J16<=0,"Habis",IF(J16<=5,"Menipis","Tersedia")) -> Habis | O16: Agus Kurniawan
A17: BAH-192 | B17: Etanol 96% | C17: Bahan Kimia | D17: Botol | E17: CV Sigma Nusantara | F17: 2025-06-18 | G17: 2025-06-21 | H17: 200 | I17: 134 | J17: =H17-I17 -> 66 | K17: 220000 | L17: =J17*K17 -> 14520000 | M17: Lemari Flammable | N17: =IF(J17<=0,"Habis",IF(J17<=5,"Menipis","Tersedia")) -> Tersedia | O17: Agus Kurniawan
A18: BAH-141 | B18: Kertas Saring Whatman | C18: Bahan Habis Pakai | D18: Pack | E18: PT Advanced Nano Tech | F18: 2025-11-26 | G18: 2025-11-27 | H18: 150 | I18: 123 | J18: =H18-I18 -> 27 | K18: 240000 | L18: =J18*K18 -> 6480000 | M18: Gudang B (Dingin) | N18: =IF(J18<=0,"Habis",IF(J18<=5,"Menipis","Tersedia")) -> Tersedia | O18: Dr. Ahmad Fauzi
A19: REA-155 | B19: Gel Red Stain | C19: Reagen | D19: Kit | E19: PT Merck Chemical Indonesia | F19: 2025-01-24 | G19: 2025-02-07 | H19: 150 | I19: 28 | J19: =H19-I19 -> 122 | K19: 650000 | L19: =J19*K19 -> 79300000 | M19: Gudang Utama A | N19: =IF(J19<=0,"Habis",IF(J19<=5,"Menipis","Tersedia")) -> Tersedia | O19: Hendra Setiawan
A20: ALA-185 | B20: Vortex Mixer | C20: Alat Laboratorium | D20: Unit | E20: CV Labware Indonesia | F20: 2025-11-01 | G20: 2025-11-03 | H20: 2 | I20: 1 | J20: =H20-I20 -> 1 | K20: 3800000 | L20: =J20*K20 -> 3800000 | M20: Rak Alat C | N20: =IF(J20<=0,"Habis",IF(J20<=5,"Menipis","Tersedia")) -> Menipis | O20: Budi Santoso, M.Si.
A21: APD-154 | B21: Sarung Tangan Nitril | C21: APD | D21: Box | E21: PT Merck Chemical Indonesia | F21: 2025-08-26 | G21: 2025-09-07 | H21: 200 | I21: 134 | J21: =H21-I21 -> 66 | K21: 85000 | L21: =J21*K21 -> 5610000 | M21: Rak Alat C | N21: =IF(J21<=0,"Habis",IF(J21<=5,"Menipis","Tersedia")) -> Tersedia | O21: Siti Aminah, S.Si.
A22: BAH-185 | B22: Asam Klorida (HCl) | C22: Bahan Kimia | D22: Botol | E22: PT Chemlab Mandiri | F22: 2025-11-02 | H22: 50 | I22: 0 | J22: =H22-I22 -> 50 | K22: 310000 | L22: =J22*K22 -> 15500000 | M22: Rak Alat C | N22: =IF(J22<=0,"Habis",IF(J22<=5,"Menipis","Tersedia")) -> Tersedia | O22: Rina Wijaya
A23: BAH-126 | B23: Tip Pipet 200µL | C23: Bahan Habis Pakai | D23: Pack | E23: PT Anugerah Analitika | F23: 2025-11-30 | H23: 20 | I23: 0 | J23: =H23-I23 -> 20 | K23: 75000 | L23: =J23*K23 -> 1500000 | M23: Lemari Flammable | N23: =IF(J23<=0,"Habis",IF(J23<=5,"Menipis","Tersedia")) -> Tersedia | O23: Fajar Nugroho
A24: BAH-107 | B24: Perak Nitrat (AgNO3) | C24: Bahan Kimia | D24: Botol | E24: PT Medika Utama | F24: 2025-08-22 | G24: 2025-09-03 | H24: 100 | I24: 81 | J24: =H24-I24 -> 19 | K24: 1750000 | L24: =J24*K24 -> 33250000 | M24: Rak Alat C | N24: =IF(J24<=0,"Habis",IF(J24<=5,"Menipis","Tersedia")) -> Tersedia | O24: Hendra Setiawan
A25: ALA-188 | B25: Timbangan Analitik | C25: Alat Laboratorium | D25: Unit | E25: CV Sigma Nusantara | F25: 2025-05-15 | G25: 2025-05-27 | H25: 5 | I25: 3 | J25: =H25-I25 -> 2 | K25: 1550000 | L25: =J25*K25 -> 3100000 | M25: Loker APD Sentral | N25: =IF(J25<=0,"Habis",IF(J25<=5,"Menipis","Tersedia")) -> Menipis | O25: Agus Kurniawan
A26: ALA-157 | B26: Timbangan Analitik | C26: Alat Laboratorium | D26: Unit | E26: CV Labware Indonesia | F26: 2025-10-04 | G26: 2025-10-19 | H26: 5 | I26: 4 | J26: =H26-I26 -> 1 | K26: 1550000 | L26: =J26*K26 -> 1550000 | M26: Gudang Utama A | N26: =IF(J26<=0,"Habis",IF(J26<=5,"Menipis","Tersedia")) -> Menipis | O26: Agus Kurniawan
A27: ALA-153 | B27: Tabung Reaksi | C27: Alat Gelas | D27: Pcs | E27: PT Advanced Nano Tech | F27: 2025-06-06 | G27: 2025-06-08 | H27: 10 | I27: 6 | J27: =H27-I27 -> 4 | K27: 12000 | L27: =J27*K27 -> 48000 | M27: Loker APD Sentral | N27: =IF(J27<=0,"Habis",IF(J27<=5,"Menipis","Tersedia")) -> Menipis | O27: Siti Aminah, S.Si.
A28: BAH-178 | B28: Parafilm M Roll | C28: Bahan Habis Pakai | D28: Pack | E28: PT Medika Utama | F28: 2025-04-06 | H28: 20 | I28: 0 | J28: =H28-I28 -> 20 | K28: 650000 | L28: =J28*K28 -> 13000000 | M28: Loker APD Sentral | N28: =IF(J28<=0,"Habis",IF(J28<=5,"Menipis","Tersedia")) -> Tersedia | O28: Hendra Setiawan
A29: REA-106 | B29: Proteinase K | C29: Reagen | D29: Kit | E29: PT Merck Chemical Indonesia | F29: 2025-04-09 | G29: 2025-04-24 | H29: 150 | I29: 113 | J29: =H29-I29 -> 37 | K29: 450000 | L29: =J29*K29 -> 16650000 | M29: Lemari Flammable | N29: =IF(J29<=0,"Habis",IF(J29<=5,"Menipis","Tersedia")) -> Tersedia | O29: Siti Aminah, S.Si.
A30: APD-150 | B30: Masker Medis 3-Ply | C30: APD | D30: Box | E30: PT Merck Chemical Indonesia | F30: 2025-04-08 | G30: 2025-04-21 | H30: 150 | I30: 145 | J30: =H30-I30 -> 5 | K30: 45000 | L30: =J30*K30 -> 225000 | M30: Loker APD Sentral | N30: =IF(J30<=0,"Habis",IF(J30<=5,"Menipis","Tersedia")) -> Menipis | O30: Dewi Lestari, Ph.D.
A31: ALA-184 | B31: Mikropipet 100-1000 µL | C31: Alat Laboratorium | D31: Unit | E31: PT Advanced Nano Tech | F31: 2025-10-17 | G31: 2025-10-30 | H31: 5 | I31: 2 | J31: =H31-I31 -> 3 | K31: 2450000 | L31: =J31*K31 -> 7350000 | M31: Gudang Utama A | N31: =IF(J31<=0,"Habis",IF(J31<=5,"Menipis","Tersedia")) -> Menipis | O31: Dr. Ahmad Fauzi
A32: ALA-177 | B32: Gelas Kimia 250mL | C32: Alat Gelas | D32: Pcs | E32: PT Medika Utama | F32: 2025-10-02 | G32: 2025-10-09 | H32: 150 | I32: 23 | J32: =H32-I32 -> 127 | K32: 45000 | L32: =J32*K32 -> 5715000 | M32: Gudang Utama A | N32: =IF(J32<=0,"Habis",IF(J32<=5,"Menipis","Tersedia")) -> Tersedia | O32: Budi Santoso, M.Si.
A33: BAH-144 | B33: Akuades Steril | C33: Bahan Kimia | D33: Botol | E33: PT Alpha Sciencetama | F33: 2025-08-30 | G33: 2025-09-09 | H33: 150 | I33: 114 | J33: =H33-I33 -> 36 | K33: 85000 | L33: =J33*K33 -> 3060000 | M33: Lemari Flammable | N33: =IF(J33<=0,"Habis",IF(J33<=5,"Menipis","Tersedia")) -> Tersedia | O33: Budi Santoso, M.Si.
A34: ALA-154 | B34: Pipet Volume 10mL | C34: Alat Gelas | D34: Pcs | E34: PT Medika Utama | F34: 2025-04-10 | G34: 2025-04-11 | H34: 10 | I34: 3 | J34: =H34-I34 -> 7 | K34: 35000 | L34: =J34*K34 -> 245000 | M34: Lemari Flammable | N34: =IF(J34<=0,"Habis",IF(J34<=5,"Menipis","Tersedia")) -> Tersedia | O34: Agus Kurniawan
A35: ALA-172 | B35: Labu Erlenmeyer 500mL | C35: Alat Gelas | D35: Pcs | E35: PT Anugerah Analitika | F35: 2025-07-12 | G35: 2025-07-17 | H35: 10 | I35: 3 | J35: =H35-I35 -> 7 | K35: 65000 | L35: =J35*K35 -> 455000 | M35: Loker APD Sentral | N35: =IF(J35<=0,"Habis",IF(J35<=5,"Menipis","Tersedia")) -> Tersedia | O35: Dewi Lestari, Ph.D.
A36: ALA-174 | B36: Gelas Kimia 250mL | C36: Alat Gelas | D36: Pcs | E36: PT Global Labora Mandiri | F36: 2025-07-04 | G36: 2025-07-11 | H36: 20 | I36: 2 | J36: =H36-I36 -> 18 | K36: 45000 | L36: =J36*K36 -> 810000 | M36: Loker APD Sentral | N36: =IF(J36<=0,"Habis",IF(J36<=5,"Menipis","Tersedia")) -> Tersedia | O36: Siti Aminah, S.Si.
A37: APD-109 | B37: Kacamata Google Safety | C37: APD | D37: Box | E37: PT Medika Utama | F37: 2025-03-25 | G37: 2025-04-07 | H37: 20 | I37: 15 | J37: =H37-I37 -> 5 | K37: 35000 | L37: =J37*K37 -> 175000 | M37: Lemari Flammable | N37: =IF(J37<=0,"Habis",IF(J37<=5,"Menipis","Tersedia")) -> Menipis | O37: Rina Wijaya
A38: ALA-122 | B38: Mikropipet 100-1000 µL | C38: Alat Laboratorium | D38: Unit | E38: PT Global Labora Mandiri | F38: 2025-09-20 | G38: 2025-09-27 | H38: 10 | I38: 2 | J38: =H38-I38 -> 8 | K38: 2450000 | L38: =J38*K38 -> 19600000 | M38: Gudang B (Dingin) | N38: =IF(J38<=0,"Habis",IF(J38<=5,"Menipis","Tersedia")) -> Tersedia | O38: Fajar Nugroho
A39: REA-113 | B39: PCR Master Mix 2X | C39: Reagen | D39: Kit | E39: PT Anugerah Analitika | F39: 2025-10-01 | G39: 2025-10-07 | H39: 200 | I39: 26 | J39: =H39-I39 -> 174 | K39: 850000 | L39: =J39*K39 -> 147900000 | M39: Rak Alat C | N39: =IF(J39<=0,"Habis",IF(J39<=5,"Menipis","Tersedia")) -> Tersedia | O39: Hendra Setiawan
A40: APD-177 | B40: Kacamata Google Safety | C40: APD | D40: Box | E40: PT Merck Chemical Indonesia | F40: 2025-12-07 | G40: 2025-12-19 | H40: 20 | I40: 13 | J40: =H40-I40 -> 7 | K40: 35000 | L40: =J40*K40 -> 245000 | M40: Gudang Utama A | N40: =IF(J40<=0,"Habis",IF(J40<=5,"Menipis","Tersedia")) -> Tersedia | O40: Hendra Setiawan
...

Sheet Data Olahan
A2: LAPORAN INVENTARIS LABORATORIUM KLINIK PAJAJARAN BARU
A4: Kode Barang | B4: Nama Barang | C4: Kategori Barang | D4: Satuan | E4: Supplier | F4: Tanggal Masuk | G4: Tanggal Keluar | H4: Jumlah Masuk | I4: Jumlah Keluar | J4: Stok Akhir | K4: Harga Satuan | L4: Total Nilai Persediaan | M4: Lokasi Penyimpanan | N4: Status | O4: PIC
A5: APD-154 | B5: Masker Medis 3-Ply | C5: APD | D5: Box | E5: CV Labware Indonesia | F5: 2025-08-25 | G5: 2025-09-07 | H5: 100 | I5: 84 | J5: =H5-I5 -> 16 | K5: 45000 | L5: =J5*K5 -> 720000 | M5: Gudang B (Dingin) | N5: =IF(J5<=0,"Habis",IF(J5<=5,"Menipis","Tersedia")) -> Tersedia | O5: Dr. Ahmad Fauzi
A6: ALA-166 | B6: Gelas Kimia 250mL | C6: Alat Gelas | D6: Pcs | E6: CV Labware Indonesia | F6: 2025-05-08 | G6: 2025-05-15 | H6: 200 | I6: 12 | J6: =H6-I6 -> 188 | K6: 45000 | L6: =J6*K6 -> 8460000 | M6: Gudang Utama A | N6: =IF(J6<=0,"Habis",IF(J6<=5,"Menipis","Tersedia")) -> Tersedia | O6: Dewi Lestari, Ph.D.
A7: ALA-145 | B7: Tabung Reaksi | C7: Alat Gelas | D7: Pcs | E7: PT Anugerah Analitika | F7: 2025-05-15 | H7: 100 | I7: 0 | J7: =H7-I7 -> 100 | K7: 12000 | L7: =J7*K7 -> 1200000 | M7: Rak Alat C | N7: =IF(J7<=0,"Habis",IF(J7<=5,"Menipis","Tersedia")) -> Tersedia | O7: Fajar Nugroho
A8: ALA-117 | B8: Mini Centrifuge | C8: Alat Laboratorium | D8: Unit | E8: CV Labware Indonesia | F8: 2025-11-11 | G8: 2025-11-14 | H8: 2 | I8: 1 | J8: =H8-I8 -> 1 | K8: 4500000 | L8: =J8*K8 -> 4500000 | M8: Lemari Flammable | N8: =IF(J8<=0,"Habis",IF(J8<=5,"Menipis","Tersedia")) -> Menipis | O8: Rina Wijaya
A9: ALA-168 | B9: Pipet Volume 10mL | C9: Alat Gelas | D9: Pcs | E9: PT Medika Utama | F9: 2025-10-09 | G9: 2025-10-20 | H9: 100 | I9: 9 | J9: =H9-I9 -> 91 | K9: 35000 | L9: =J9*K9 -> 3185000 | M9: Rak Alat C | N9: =IF(J9<=0,"Habis",IF(J9<=5,"Menipis","Tersedia")) -> Tersedia | O9: Rina Wijaya
A10: APD-164 | B10: Jas Laboratorium | C10: APD | D10: Box | E10: PT Global Labora Mandiri | F10: 2025-05-03 | H10: 10 | I10: 0 | J10: =H10-I10 -> 10 | K10: 150000 | L10: =J10*K10 -> 1500000 | M10: Lemari Flammable | N10: =IF(J10<=0,"Habis",IF(J10<=5,"Menipis","Tersedia")) -> Tersedia | O10: Rina Wijaya
A11: ALA-184 | B11: pH Meter | C11: Alat Laboratorium | D11: Unit | E11: CV Biotech Pratama | F11: 2025-07-16 | G11: 2025-07-18 | H11: 5 | I11: 2 | J11: =H11-I11 -> 3 | K11: 1850000 | L11: =J11*K11 -> 5550000 | M11: Gudang B (Dingin) | N11: =IF(J11<=0,"Habis",IF(J11<=5,"Menipis","Tersedia")) -> Menipis | O11: Siti Aminah, S.Si.
A12: REA-121 | B12: Buffer TAE 50X | C12: Reagen | D12: Kit | E12: PT Merck Chemical Indonesia | F12: 2025-08-01 | H12: 100 | I12: 0 | J12: =H12-I12 -> 100 | K12: 350000 | L12: =J12*K12 -> 35000000 | M12: Lemari Flammable | N12: =IF(J12<=0,"Habis",IF(J12<=5,"Menipis","Tersedia")) -> Tersedia | O12: Dewi Lestari, Ph.D.
A13: ALA-179 | B13: Vortex Mixer | C13: Alat Laboratorium | D13: Unit | E13: PT Chemlab Mandiri | F13: 2025-05-17 | H13: 5 | I13: 0 | J13: =H13-I13 -> 5 | K13: 3800000 | L13: =J13*K13 -> 19000000 | M13: Gudang Utama A | N13: =IF(J13<=0,"Habis",IF(J13<=5,"Menipis","Tersedia")) -> Menipis | O13: Budi Santoso, M.Si.
A14: BAH-199 | B14: Kertas Saring Whatman | C14: Bahan Habis Pakai | D14: Pack | E14: PT Global Labora Mandiri | F14: 2025-06-17 | H14: 100 | I14: 0 | J14: =H14-I14 -> 100 | K14: 240000 | L14: =J14*K14 -> 24000000 | M14: Rak Alat C | N14: =IF(J14<=0,"Habis",IF(J14<=5,"Menipis","Tersedia")) -> Tersedia | O14: Agus Kurniawan
A15: APD-142 | B15: Masker Medis 3-Ply | C15: APD | D15: Box | E15: PT Medika Utama | F15: 2025-05-15 | G15: 2025-05-22 | H15: 100 | I15: 21 | J15: =H15-I15 -> 79 | K15: 45000 | L15: =J15*K15 -> 3555000 | M15: Gudang Utama A | N15: =IF(J15<=0,"Habis",IF(J15<=5,"Menipis","Tersedia")) -> Tersedia | O15: Rina Wijaya
A16: BAH-194 | B16: Metanol P.A. | C16: Bahan Kimia | D16: Botol | E16: PT Chemlab Mandiri | F16: 2025-09-05 | G16: 2025-09-13 | H16: 150 | I16: 43 | J16: =H16-I16 -> 107 | K16: 280000 | L16: =J16*K16 -> 29960000 | M16: Loker APD Sentral | N16: =IF(J16<=0,"Habis",IF(J16<=5,"Menipis","Tersedia")) -> Tersedia | O16: Hendra Setiawan
A17: BAH-151 | B17: Parafilm M Roll | C17: Bahan Habis Pakai | D17: Pack | E17: PT Global Labora Mandiri | F17: 2025-10-27 | G17: 2025-11-08 | H17: 50 | I17: 32 | J17: =H17-I17 -> 18 | K17: 650000 | L17: =J17*K17 -> 11700000 | M17: Loker APD Sentral | N17: =IF(J17<=0,"Habis",IF(J17<=5,"Menipis","Tersedia")) -> Tersedia | O17: Fajar Nugroho
A18: ALA-156 | B18: Tabung Reaksi | C18: Alat Gelas | D18: Pcs | E18: CV Biotech Pratama | F18: 2025-01-02 | G18: 2025-01-08 | H18: 100 | I18: 7 | J18: =H18-I18 -> 93 | K18: 12000 | L18: =J18*K18 -> 1116000 | M18: Gudang Utama A | N18: =IF(J18<=0,"Habis",IF(J18<=5,"Menipis","Tersedia")) -> Tersedia | O18: Fajar Nugroho
A19: REA-113 | B19: PCR Master Mix 2X | C19: Reagen | D19: Kit | E19: PT Advanced Nano Tech | F19: 2025-03-13 | G19: 2025-03-22 | H19: 100 | I19: 100 | J19: =H19-I19 -> 0 | K19: 850000 | L19: =J19*K19 -> 0 | M19: Lemari Flammable | N19: =IF(J19<=0,"Habis",IF(J19<=5,"Menipis","Tersedia")) -> Habis | O19: Agus Kurniawan
A20: BAH-192 | B20: Etanol 96% | C20: Bahan Kimia | D20: Botol | E20: CV Sigma Nusantara | F20: 2025-06-18 | G20: 2025-06-21 | H20: 200 | I20: 134 | J20: =H20-I20 -> 66 | K20: 220000 | L20: =J20*K20 -> 14520000 | M20: Lemari Flammable | N20: =IF(J20<=0,"Habis",IF(J20<=5,"Menipis","Tersedia")) -> Tersedia | O20: Agus Kurniawan
A21: BAH-141 | B21: Kertas Saring Whatman | C21: Bahan Habis Pakai | D21: Pack | E21: PT Advanced Nano Tech | F21: 2025-11-26 | G21: 2025-11-27 | H21: 150 | I21: 123 | J21: =H21-I21 -> 27 | K21: 240000 | L21: =J21*K21 -> 6480000 | M21: Gudang B (Dingin) | N21: =IF(J21<=0,"Habis",IF(J21<=5,"Menipis","Tersedia")) -> Tersedia | O21: Dr. Ahmad Fauzi
A22: REA-155 | B22: Gel Red Stain | C22: Reagen | D22: Kit | E22: PT Merck Chemical Indonesia | F22: 2025-01-24 | G22: 2025-02-07 | H22: 150 | I22: 28 | J22: =H22-I22 -> 122 | K22: 650000 | L22: =J22*K22 -> 79300000 | M22: Gudang Utama A | N22: =IF(J22<=0,"Habis",IF(J22<=5,"Menipis","Tersedia")) -> Tersedia | O22: Hendra Setiawan
A23: ALA-185 | B23: Vortex Mixer | C23: Alat Laboratorium | D23: Unit | E23: CV Labware Indonesia | F23: 2025-11-01 | G23: 2025-11-03 | H23: 2 | I23: 1 | J23: =H23-I23 -> 1 | K23: 3800000 | L23: =J23*K23 -> 3800000 | M23: Rak Alat C | N23: =IF(J23<=0,"Habis",IF(J23<=5,"Menipis","Tersedia")) -> Menipis | O23: Budi Santoso, M.Si.
A24: APD-154 | B24: Sarung Tangan Nitril | C24: APD | D24: Box | E24: PT Merck Chemical Indonesia | F24: 2025-08-26 | G24: 2025-09-07 | H24: 200 | I24: 134 | J24: =H24-I24 -> 66 | K24: 85000 | L24: =J24*K24 -> 5610000 | M24: Rak Alat C | N24: =IF(J24<=0,"Habis",IF(J24<=5,"Menipis","Tersedia")) -> Tersedia | O24: Siti Aminah, S.Si.
A25: BAH-185 | B25: Asam Klorida (HCl) | C25: Bahan Kimia | D25: Botol | E25: PT Chemlab Mandiri | F25: 2025-11-02 | H25: 50 | I25: 0 | J25: =H25-I25 -> 50 | K25: 310000 | L25: =J25*K25 -> 15500000 | M25: Rak Alat C | N25: =IF(J25<=0,"Habis",IF(J25<=5,"Menipis","Tersedia")) -> Tersedia | O25: Rina Wijaya
A26: BAH-126 | B26: Tip Pipet 200µL | C26: Bahan Habis Pakai | D26: Pack | E26: PT Anugerah Analitika | F26: 2025-11-30 | H26: 20 | I26: 0 | J26: =H26-I26 -> 20 | K26: 75000 | L26: =J26*K26 -> 1500000 | M26: Lemari Flammable | N26: =IF(J26<=0,"Habis",IF(J26<=5,"Menipis","Tersedia")) -> Tersedia | O26: Fajar Nugroho
A27: BAH-107 | B27: Perak Nitrat (AgNO3) | C27: Bahan Kimia | D27: Botol | E27: PT Medika Utama | F27: 2025-08-22 | G27: 2025-09-03 | H27: 100 | I27: 81 | J27: =H27-I27 -> 19 | K27: 1750000 | L27: =J27*K27 -> 33250000 | M27: Rak Alat C | N27: =IF(J27<=0,"Habis",IF(J27<=5,"Menipis","Tersedia")) -> Tersedia | O27: Hendra Setiawan
A28: ALA-188 | B28: Timbangan Analitik | C28: Alat Laboratorium | D28: Unit | E28: CV Sigma Nusantara | F28: 2025-05-15 | G28: 2025-05-27 | H28: 5 | I28: 3 | J28: =H28-I28 -> 2 | K28: 1550000 | L28: =J28*K28 -> 3100000 | M28: Loker APD Sentral | N28: =IF(J28<=0,"Habis",IF(J28<=5,"Menipis","Tersedia")) -> Menipis | O28: Agus Kurniawan
A29: ALA-157 | B29: Timbangan Analitik | C29: Alat Laboratorium | D29: Unit | E29: CV Labware Indonesia | F29: 2025-10-04 | G29: 2025-10-19 | H29: 5 | I29: 4 | J29: =H29-I29 -> 1 | K29: 1550000 | L29: =J29*K29 -> 1550000 | M29: Gudang Utama A | N29: =IF(J29<=0,"Habis",IF(J29<=5,"Menipis","Tersedia")) -> Menipis | O29: Agus Kurniawan
A30: ALA-153 | B30: Tabung Reaksi | C30: Alat Gelas | D30: Pcs | E30: PT Advanced Nano Tech | F30: 2025-06-06 | G30: 2025-06-08 | H30: 10 | I30: 6 | J30: =H30-I30 -> 4 | K30: 12000 | L30: =J30*K30 -> 48000 | M30: Loker APD Sentral | N30: =IF(J30<=0,"Habis",IF(J30<=5,"Menipis","Tersedia")) -> Menipis | O30: Siti Aminah, S.Si.
A31: BAH-178 | B31: Parafilm M Roll | C31: Bahan Habis Pakai | D31: Pack | E31: PT Medika Utama | F31: 2025-04-06 | H31: 20 | I31: 0 | J31: =H31-I31 -> 20 | K31: 650000 | L31: =J31*K31 -> 13000000 | M31: Loker APD Sentral | N31: =IF(J31<=0,"Habis",IF(J31<=5,"Menipis","Tersedia")) -> Tersedia | O31: Hendra Setiawan
A32: REA-106 | B32: Proteinase K | C32: Reagen | D32: Kit | E32: PT Merck Chemical Indonesia | F32: 2025-04-09 | G32: 2025-04-24 | H32: 150 | I32: 113 | J32: =H32-I32 -> 37 | K32: 450000 | L32: =J32*K32 -> 16650000 | M32: Lemari Flammable | N32: =IF(J32<=0,"Habis",IF(J32<=5,"Menipis","Tersedia")) -> Tersedia | O32: Siti Aminah, S.Si.
A33: APD-150 | B33: Masker Medis 3-Ply | C33: APD | D33: Box | E33: PT Merck Chemical Indonesia | F33: 2025-04-08 | G33: 2025-04-21 | H33: 150 | I33: 145 | J33: =H33-I33 -> 5 | K33: 45000 | L33: =J33*K33 -> 225000 | M33: Loker APD Sentral | N33: =IF(J33<=0,"Habis",IF(J33<=5,"Menipis","Tersedia")) -> Menipis | O33: Dewi Lestari, Ph.D.
A34: ALA-184 | B34: Mikropipet 100-1000 µL | C34: Alat Laboratorium | D34: Unit | E34: PT Advanced Nano Tech | F34: 2025-10-17 | G34: 2025-10-30 | H34: 5 | I34: 2 | J34: =H34-I34 -> 3 | K34: 2450000 | L34: =J34*K34 -> 7350000 | M34: Gudang Utama A | N34: =IF(J34<=0,"Habis",IF(J34<=5,"Menipis","Tersedia")) -> Menipis | O34: Dr. Ahmad Fauzi
A35: ALA-177 | B35: Gelas Kimia 250mL | C35: Alat Gelas | D35: Pcs | E35: PT Medika Utama | F35: 2025-10-02 | G35: 2025-10-09 | H35: 150 | I35: 23 | J35: =H35-I35 -> 127 | K35: 45000 | L35: =J35*K35 -> 5715000 | M35: Gudang Utama A | N35: =IF(J35<=0,"Habis",IF(J35<=5,"Menipis","Tersedia")) -> Tersedia | O35: Budi Santoso, M.Si.
A36: BAH-144 | B36: Akuades Steril | C36: Bahan Kimia | D36: Botol | E36: PT Alpha Sciencetama | F36: 2025-08-30 | G36: 2025-09-09 | H36: 150 | I36: 114 | J36: =H36-I36 -> 36 | K36: 85000 | L36: =J36*K36 -> 3060000 | M36: Lemari Flammable | N36: =IF(J36<=0,"Habis",IF(J36<=5,"Menipis","Tersedia")) -> Tersedia | O36: Budi Santoso, M.Si.
A37: ALA-154 | B37: Pipet Volume 10mL | C37: Alat Gelas | D37: Pcs | E37: PT Medika Utama | F37: 2025-04-10 | G37: 2025-04-11 | H37: 10 | I37: 3 | J37: =H37-I37 -> 7 | K37: 35000 | L37: =J37*K37 -> 245000 | M37: Lemari Flammable | N37: =IF(J37<=0,"Habis",IF(J37<=5,"Menipis","Tersedia")) -> Tersedia | O37: Agus Kurniawan
A38: ALA-172 | B38: Labu Erlenmeyer 500mL | C38: Alat Gelas | D38: Pcs | E38: PT Anugerah Analitika | F38: 2025-07-12 | G38: 2025-07-17 | H38: 10 | I38: 3 | J38: =H38-I38 -> 7 | K38: 65000 | L38: =J38*K38 -> 455000 | M38: Loker APD Sentral | N38: =IF(J38<=0,"Habis",IF(J38<=5,"Menipis","Tersedia")) -> Tersedia | O38: Dewi Lestari, Ph.D.
A39: ALA-174 | B39: Gelas Kimia 250mL | C39: Alat Gelas | D39: Pcs | E39: PT Global Labora Mandiri | F39: 2025-07-04 | G39: 2025-07-11 | H39: 20 | I39: 2 | J39: =H39-I39 -> 18 | K39: 45000 | L39: =J39*K39 -> 810000 | M39: Loker APD Sentral | N39: =IF(J39<=0,"Habis",IF(J39<=5,"Menipis","Tersedia")) -> Tersedia | O39: Siti Aminah, S.Si.
A40: APD-109 | B40: Kacamata Google Safety | C40: APD | D40: Box | E40: PT Medika Utama | F40: 2025-03-25 | G40: 2025-04-07 | H40: 20 | I40: 15 | J40: =H40-I40 -> 5 | K40: 35000 | L40: =J40*K40 -> 175000 | M40: Lemari Flammable | N40: =IF(J40<=0,"Habis",IF(J40<=5,"Menipis","Tersedia")) -> Menipis | O40: Rina Wijaya
A41: ALA-122 | B41: Mikropipet 100-1000 µL | C41: Alat Laboratorium | D41: Unit | E41: PT Global Labora Mandiri | F41: 2025-09-20 | G41: 2025-09-27 | H41: 10 | I41: 2 | J41: =H41-I41 -> 8 | K41: 2450000 | L41: =J41*K41 -> 19600000 | M41: Gudang B (Dingin) | N41: =IF(J41<=0,"Habis",IF(J41<=5,"Menipis","Tersedia")) -> Tersedia | O41: Fajar Nugroho
A42: REA-113 | B42: PCR Master Mix 2X | C42: Reagen | D42: Kit | E42: PT Anugerah Analitika | F42: 2025-10-01 | G42: 2025-10-07 | H42: 200 | I42: 26 | J42: =H42-I42 -> 174 | K42: 850000 | L42: =J42*K42 -> 147900000 | M42: Rak Alat C | N42: =IF(J42<=0,"Habis",IF(J42<=5,"Menipis","Tersedia")) -> Tersedia | O42: Hendra Setiawan
...

Sheet PIVOT
A1: Total Nilai Persediaan | E1: Nilai Persediaan Per Supplier | H1: Top 5 Barang berdasarkan Nilai Persediaan | K1: Status Inventaris | N1: Barang Masuk dan Keluar
A2: Status | B2: Menipis | E2: Status | F2: (All) | K2: Supplier | L2: (All) | N2: Supplier | O2: (All)
A3: Supplier | B3: PT Global Labora Mandiri | E3: Kategori Barang | F3: Bahan Kimia | H3: Row Labels | I3: Sum of Total Nilai Persediaan | K3: Kategori Barang | L3: Bahan Kimia | N3: Kategori Barang | O3: Bahan Kimia
H4: Akuades Steril | I4: 7310000
A5: Kategori Barang | B5: Sum of Total Nilai Persediaan | E5: Status | F5: Sum of Total Nilai Persediaan | H5: Metanol P.A. | I5: 107520000 | K5: Status Barang | L5: Count of Kode Barang | N5: Sum of Jumlah Masuk | O5: Sum of Jumlah Keluar
A6: Grand Total | E6: CV Labware Indonesia | F6: 29385000 | H6: Etanol 96% | I6: 152900000 | K6: Habis | L6: 1 | N6: 3840 | O6: 1771
E7: CV Sigma Nusantara | F7: 64520000 | H7: Asam Klorida (HCl) | I7: 216380000 | K7: Menipis | L7: 11
E8: PT Advanced Nano Tech | F8: 1330000 | H8: Perak Nitrat (AgNO3) | I8: 360500000 | K8: Tersedia | L8: 37
E9: PT Alpha Sciencetama | F9: 137260000 | H9: Grand Total | I9: 844610000 | K9: Grand Total | L9: 49
E10: PT Anugerah Analitika | F10: 165325000
E11: PT Chemlab Mandiri | F11: 93370000
E12: PT Global Labora Mandiri | F12: 240370000
E13: PT Medika Utama | F13: 83060000
E14: PT Merck Chemical Indonesia | F14: 29990000
E15: Grand Total | F15: 844610000

Sheet Dashboard
A1: DASHBOARD INVENTARIS LABORATORIUM
A3: Total Nilai Persediaan | B3: Jumlah Supplier | C3: Jumlah Barang Menipis | D3: Total Barang Masuk | E3: Total Barag Keluar
A4: =SUM(GETPIVOTDATA("Total Nilai Persediaan",PIVOT!$A$5)) -> 0 | B4: =SUMPRODUCT(('Raw Data'!E2:E311<>"")/COUNTIF('Raw Data'!E2:E311,'Raw Data'!E2:E311&"")) -> 10 | C4: =SUM(GETPIVOTDATA("Kode Barang",PIVOT!$K$5,"Status","Menipis")) -> 11 | D4: =SUM(GETPIVOTDATA("Sum of Jumlah Masuk",PIVOT!$N$5)) -> 3840 | E4: =SUM(GETPIVOTDATA("Sum of Jumlah Keluar",PIVOT!$N$5)) -> 1771

Sheet Search Inventory
A1: Search Inventory
A3: Kode Barang: | B3: ALA-157
A5: Informasi Barang | B5: Hasil
A6: Nama Barang | B6: =INDEX('Raw Data'!B2:B311,MATCH(B3,'Raw Data'!A2:A311,0)) -> Timbangan Analitik
A7: Kategori Barang | B7: =INDEX('Raw Data'!C2:C311,MATCH(B3,'Raw Data'!A2:A311,0)) -> Alat Laboratorium
A8: Supplier | B8: =INDEX('Raw Data'!E2:E311,MATCH(B3,'Raw Data'!A2:A311,0)) -> CV Labware Indonesia
A9: Stok Akhir | B9: =INDEX('Raw Data'!J2:J311,MATCH(B3,'Raw Data'!A2:A311,0)) -> 1
A10: Status | B10: =INDEX('Raw Data'!N2:N311,MATCH(B3,'Raw Data'!A2:A311,0)) -> Menipis
A11: Lokasi Penyimpanan | B11: =INDEX('Raw Data'!M2:M311,MATCH(B3,'Raw Data'!A2:A311,0)) -> Gudang Utama A
A12: PIC | B12: =INDEX('Raw Data'!O2:O311,MATCH(B3,'Raw Data'!A2:A311,0)) -> Agus Kurniawan
